<?xml version="1.0" encoding="utf-8"?>
<!-- This URDF was automatically created by SolidWorks to URDF Exporter! Originally created by Stephen Brawner (brawner@gmail.com) 
     Commit Version: 1.6.0-4-g7f85cfe  Build Version: 1.6.7995.38578
     For more information, please see http://wiki.ros.org/sw_urdf_exporter -->
<robot
  name="ER15-1400">
  <link
    name="base_link">
    <inertial>
      <origin
        xyz="-0.022737 0.1087 -0.0045081"
        rpy="0 0 0" />
      <mass
        value="17.552" />
      <inertia
        ixx="0.15174"
        ixy="-0.0035317"
        ixz="-0.00032694"
        iyy="0.26069"
        iyz="7.7831E-05"
        izz="0.22707" />
    </inertial>
    <visual>
      <origin
        xyz="0 0 0"
        rpy="0 0 0" />
      <geometry>
        <mesh
          filename="package://ER15-1400/meshes/base_link.STL" />
      </geometry>
      <material
        name="">
        <color
          rgba="0.79216 0.81961 0.93333 1" />
      </material>
    </visual>
    <collision>
      <origin
        xyz="0 0 0"
        rpy="0 0 0" />
      <geometry>
        <mesh
          filename="package://ER15-1400/meshes/base_link.STL" />
      </geometry>
    </collision>
  </link>
  <link
    name="link_1">
    <inertial>
      <origin
        xyz="0.087027 0.16667 0.0070087"
        rpy="0 0 0" />
      <mass
        value="25.756" />
      <inertia
        ixx="0.50657"
        ixy="-0.14782"
        ixz="0.063079"
        iyy="0.65337"
        iyz="0.05515"
        izz="0.50525" />
    </inertial>
    <visual>
      <origin
        xyz="0 0 0"
        rpy="0 0 0" />
      <geometry>
        <mesh
          filename="package://ER15-1400/meshes/link_1.STL" />
      </geometry>
      <material
        name="">
        <color
          rgba="0.79216 0.81961 0.93333 1" />
      </material>
    </visual>
    <collision>
      <origin
        xyz="0 0 0"
        rpy="0 0 0" />
      <geometry>
        <mesh
          filename="package://ER15-1400/meshes/link_1.STL" />
      </geometry>
    </collision>
  </link>
  <joint
    name="joint_1"
    type="continuous">
    <origin
      xyz="0.013059 0.0045 0.196"
      rpy="1.5708 0 0" />
    <parent
      link="base_link" />
    <child
      link="link_1" />
    <axis
      xyz="0 1 0" />
  </joint>
  <link
    name="link_2">
    <inertial>
      <origin
        xyz="0.0052157 0.24914 0.083905"
        rpy="0 0 0" />
      <mass
        value="9.936" />
      <inertia
        ixx="0.43323"
        ixy="0.0053716"
        ixz="-4.4126E-05"
        iyy="0.026505"
        iyz="-0.015746"
        izz="0.44703" />
    </inertial>
    <visual>
      <origin
        xyz="0 0 0.02"
        rpy="0 0 0" />
      <geometry>
        <mesh
          filename="package://ER15-1400/meshes/link_2.STL" />
      </geometry>
      <material
        name="">
        <color
          rgba="0.79216 0.81961 0.93333 1" />
      </material>
    </visual>
    <collision>
      <origin
        xyz="0 0 0"
        rpy="0 0 0" />
      <geometry>
        <mesh
          filename="package://ER15-1400/meshes/link_2.STL" />
      </geometry>
    </collision>
  </link>
  <joint
    name="joint_2"
    type="continuous">
    <origin
      xyz="0.18 0.234 0.0615"
      rpy="0 0 0" />
    <parent
      link="link_1" />
    <child
      link="link_2" />
    <axis
      xyz="0 0 1" />
  </joint>
  <link
    name="link_3">
    <inertial>
      <origin
        xyz="0.042899 0.082142 -0.030195"
        rpy="0 0 0" />
      <mass
        value="15.122" />
      <inertia
        ixx="0.26566"
        ixy="-0.045696"
        ixz="-0.002732"
        iyy="0.22992"
        iyz="-0.0036396"
        izz="0.17797" />
    </inertial>
    <visual>
      <origin
        xyz="0 0 0"
        rpy="0 0 0" />
      <geometry>
        <mesh
          filename="package://ER15-1400/meshes/link_3.STL" />
      </geometry>
      <material
        name="">
        <color
          rgba="0.79216 0.81961 0.93333 1" />
      </material>
    </visual>
    <collision>
      <origin
        xyz="0 0 0"
        rpy="0 0 0" />
      <geometry>
        <mesh
          filename="package://ER15-1400/meshes/link_3.STL" />
      </geometry>
    </collision>
  </link>
  <joint
    name="joint_3"
    type="continuous">
    <origin
      xyz="0 0.58 0"
      rpy="0 0 0" />
    <parent
      link="link_2" />
    <child
      link="link_3" />
    <axis
      xyz="0 0 1" />
  </joint>
  <link
    name="link_4">
    <inertial>
      <origin
        xyz="0.20271 0.0011368 7.6237E-05"
        rpy="0 0 0" />
      <mass
        value="8.0966" />
      <inertia
        ixx="0.031521"
        ixy="8.0776E-05"
        ixz="-5.353E-05"
        iyy="0.143"
        iyz="-9.1869E-07"
        izz="0.1313" />
    </inertial>
    <visual>
      <origin
        xyz="0 0 0"
        rpy="0 0 0" />
      <geometry>
        <mesh
          filename="package://ER15-1400/meshes/link_4.STL" />
      </geometry>
      <material
        name="">
        <color
          rgba="0.79216 0.81961 0.93333 1" />
      </material>
    </visual>
    <collision>
      <origin
        xyz="0 0 0"
        rpy="0 0 0" />
      <geometry>
        <mesh
          filename="package://ER15-1400/meshes/link_4.STL" />
      </geometry>
    </collision>
  </link>
  <joint
    name="joint_4"
    type="continuous">
    <origin
      xyz="0.20999 0.16 -0.0628"
      rpy="0 0 0" />
    <parent
      link="link_3" />
    <child
      link="link_4" />
    <axis
      xyz="1 0 0" />
  </joint>
  <link
    name="link_5">
    <inertial>
      <origin
        xyz="0.02152 5.3039E-05 7.1266E-05"
        rpy="0 0 0" />
      <mass
        value="1.7011" />
      <inertia
        ixx="0.0030157"
        ixy="2.1898E-06"
        ixz="2.3695E-06"
        iyy="0.0048424"
        iyz="-5.0731E-06"
        izz="0.0051235" />
    </inertial>
    <visual>
      <origin
        xyz="0 0 0"
        rpy="0 0 0" />
      <geometry>
        <mesh
          filename="package://ER15-1400/meshes/link_5.STL" />
      </geometry>
      <material
        name="">
        <color
          rgba="0.79216 0.81961 0.93333 1" />
      </material>
    </visual>
    <collision>
      <origin
        xyz="0 0 0"
        rpy="0 0 0" />
      <geometry>
        <mesh
          filename="package://ER15-1400/meshes/link_5.STL" />
      </geometry>
    </collision>
  </link>
  <joint
    name="joint_5"
    type="continuous">
    <origin
      xyz="0.42951 0 0"
      rpy="0 0 0" />
    <parent
      link="link_4" />
    <child
      link="link_5" />
    <axis
      xyz="0 0 1" />
  </joint>
  <link
    name="link_6">
    <inertial>
      <origin
        xyz="0.0072982 -0.00012955 1.29E-05"
        rpy="0 0 0" />
      <mass
        value="0.059879" />
      <inertia
        ixx="3.8912E-05"
        ixy="4.4278E-08"
        ixz="-5.8775E-09"
        iyy="2.0733E-05"
        iyz="-2.3336E-08"
        izz="2.0538E-05" />
    </inertial>
    <visual>
      <origin
        xyz="0 0 0"
        rpy="0 0 0" />
      <geometry>
        <mesh
          filename="package://ER15-1400/meshes/link_6.STL" />
      </geometry>
      <material
        name="">
        <color
          rgba="0.79216 0.81961 0.93333 1" />
      </material>
    </visual>
    <collision>
      <origin
        xyz="0 0 0"
        rpy="0 0 0" />
      <geometry>
        <mesh
          filename="package://ER15-1400/meshes/link_6.STL" />
      </geometry>
    </collision>
  </link>
  <joint
    name="joint_6"
    type="continuous">
    <origin
      xyz="0.1 0 0"
      rpy="-0.0013162 0 0" />
    <parent
      link="link_5" />
    <child
      link="link_6" />
    <axis
      xyz="1 0 0" />
  </joint>
</robot>